Workbook

Sheet 00_Overview
A1: HW03 GUI CHECKLIST — DETAILED EXCEL VERSION
A3: Nội dung được chuyển trực tiếp từ các bảng Markdown, giữ nguyên cấu trúc và mức độ chi tiết.
A5: TEST CONTEXT | F5: ALLOCATION FROM MARKDOWN
A6: Field | B6: Value | F6: IA category | G6: Required minimum | H6: Designed
A7: Test date | B7: 23/07/2026 | F7: IA-01 General UI standards | G7: 12 | H7: 12
A8: Backend | B8: http://localhost:3000 | F8: IA-02 Forms | G8: 12 | H8: 12
A9: Frontend Web | B9: http://localhost:5173 | F9: IA-03 Navigation | G9: 10 | H9: 10
A10: Frontend Admin | B10: http://localhost:5174 | F10: IA-04 Feedback/state | G10: 12 | H10: 12
A11: Browser / OS | B11: Chrome / Windows | F11: Total | G11: 46 | H11: 46
A12: Viewport | B12: 1440 × 900
A13: Account | B13: regular user for Cart, Checkout, Coupon section, and Checkout Success; admin account for Admin Coupon Management
A14: Evidence directory | B14: ./evidence/hw03/Chrome
A15: Method | B15: black-box GUI testing
A18: CHECKLIST SUMMARY
A20: Dataset | B20: Items | C20: Passed | D20: Failed | E20: Blocked | G20: SHEET GUIDE
A21: GUI checklist | B21: 46 | C21: 30 | D21: 13 | E21: 3 | G21: 01_GUI Checklist | H21: 46 test cases từ bảng GUI checklist
A22: Human-review additions | B22: 5 | C22: 2 | D22: 3 | E22: 0 | G22: 02_Human Review | H22: 5 mục bổ sung từ Human-review additions
A23: Combined | B23: 51 | C23: 32 | D23: 16 | E23: 3 | G23: 03_All Items | H23: Bảng tổng hợp 51 mục đã chuẩn hóa cột
G24: 04_Analysis | H24: Thống kê theo IA và màn hình

Sheet 01_GUI Checklist
A1: GUI CHECKLIST — 46 ITEMS
A2: Giữ nguyên 8 cột và toàn bộ nội dung từ bảng “GUI checklist” trong file Markdown.
A4: ID | B4: Screen | C4: IA | D4: Check / observable expected result | E4: Test data or precondition | F4: Status | G4: Origin | H4: Evidence / notes
A5: GUI-01 | B5: Cart | C5: IA-01 | D5: Tiêu đề trang và toàn bộ nhãn chính hiển thị rõ ràng, thống nhất bằng tiếng Việt, không có chuỗi lỗi font hoặc ký tự bị vỡ. | E5: User thường đã đăng nhập; giỏ có ít nhất 1 sản phẩm. | F5: PASSED | G5: AI
A6: GUI-02 | B6: Cart | C6: IA-01 | D6: Danh sách sản phẩm thể hiện rõ các thông tin Sản phẩm, Đơn giá, Số lượng, Thành tiền và Thao tác; các cột thẳng hàng, không chồng lấn tại viewport 1440 × 900. | E6: Giỏ có ít nhất 2 sản phẩm với tên dài/ngắn khác nhau. | F6: PASSED | G6: AI
A7: GUI-03 | B7: Cart | C7: IA-01 | D7: Đơn giá, thành tiền từng dòng và Tổng cộng dùng ký hiệu ₫, có phân cách hàng nghìn và cùng một quy tắc định dạng. | E7: Giỏ có ít nhất 1 sản phẩm; tổng tiền từ 1.000 ₫ trở lên. | F7: PASSED | G7: AI
A8: GUI-04 | B8: Checkout | C8: IA-01 | D8: Tiêu đề Checkout/Thanh toán, thông tin giao hàng và phần tóm tắt đơn hàng có phân cấp thị giác rõ, không bị cắt hoặc chồng lấn tại viewport 1440 × 900. | E8: User thường đã đăng nhập; giỏ không rỗng; mở Checkout. | F8: PASSED | G8: AI
A9: GUI-05 | B9: Checkout | C9: IA-01 | D9: Tên sản phẩm, số lượng, giá, tổng tiền và nút hoàn tất thanh toán dễ đọc; nút hành động chính có kiểu hiển thị nhất quán với hành động tích cực. | E9: Checkout có ít nhất 2 sản phẩm. | F9: PASSED | G9: AI
A10: GUI-06 | B10: Coupon section | C10: IA-01 | D10: Nhãn/placeholder ô mã giảm giá và nút áp dụng mô tả rõ mục đích, dùng ngôn ngữ nhất quán và không phụ thuộc riêng vào biểu tượng. | E10: User ở Checkout; khu vực coupon đang hiển thị. | F10: PASSED | G10: AI
A11: GUI-07 | B11: Coupon section | C11: IA-01 | D11: Giá trị giảm, tổng trước giảm và tổng sau giảm dùng ký hiệu ₫, phân cách hàng nghìn; phần trăm dùng % đúng và dễ phân biệt. | E11: Giỏ đủ điều kiện dùng một coupon percent và một coupon fixed. | F11: FAILED | G11: AI | H11: Coupon SAVE10 tăng giá thay vì giảm, sai logic áp dụng, không phải lỗi định dạng. Evidence: GUI_07_49.png Path: ../evidence/hw03/Chrome/GUI_07_49.png
A12: GUI-08 | B12: Checkout Success | C12: IA-01 | D12: Trạng thái đặt hàng thành công nổi bật, dễ nhận biết, không chỉ truyền đạt bằng màu sắc và không lẫn với nội dung phụ. | E12: Hoàn tất một đơn hàng hợp lệ. | F12: PASSED | G12: AI
A13: GUI-09 | B13: Checkout Success | C13: IA-01 | D13: Mã đơn, tổng tiền và thông tin xác nhận (nếu hiển thị) có nhãn rõ, định dạng nhất quán và không bị cắt ở 1440 × 900. | E13: Vừa hoàn tất một đơn hàng có tổng từ 1.000 ₫ trở lên. | F13: PASSED | G13: AI
A14: GUI-10 | B14: Admin Coupon Management | C14: IA-01 | D14: Tiêu đề quản lý coupon, khu vực tạo mới và danh sách coupon có phân cấp rõ; bảng không chồng lấn hoặc mất cột ở 1440 × 900. | E14: Admin đã đăng nhập; mở quản lý coupon; có ít nhất 2 coupon. | F14: PASSED | G14: AI
A15: GUI-11 | B15: Admin Coupon Management | C15: IA-01 | D15: Các cột Mã, Loại, Giá trị, Đơn tối thiểu, Hết hạn, Giới hạn/người và Hành động có nhãn dễ hiểu, căn chỉnh nhất quán. | E15: Danh sách có cả coupon percent và fixed. | F15: PASSED | G15: AI
A16: GUI-12 | B16: Admin Coupon Management | C16: IA-01 | D16: Ngày hết hạn, giá trị coupon, đơn tối thiểu và số lượt dùng được định dạng theo đúng loại dữ liệu; coupon hết hạn được phân biệt bằng cả chữ và kiểu hiển thị dễ đọc. | E16: Có coupon còn hạn và coupon hết hạn. | F16: PASSED | G16: AI
A17: GUI-13 | B17: Cart | C17: IA-02 | D17: Điều khiển số lượng có nhãn/biểu tượng dễ hiểu, vùng bấm rõ ràng và không cho người dùng tạo số lượng nhỏ hơn 1. | E17: Giỏ có 1 sản phẩm với số lượng 1. | F17: BLOCKED | G17: AI | H17: Không thể kiểm tra min-quantity vì control tăng/giảm số lượng không tồn tại. Evidence: GUI_13_14.png Path: ../evidence/hw03/Chrome/GUI_13_14.png
A18: GUI-14 | B18: Cart | C18: IA-02 | D18: Khi thay đổi số lượng bằng bàn phím hoặc điều khiển tăng/giảm, focus vẫn nhìn thấy và thứ tự Tab đi theo trình tự thị giác hợp lý. | E18: Giỏ có ít nhất 2 sản phẩm; thao tác chỉ bằng bàn phím. | F18: BLOCKED | G18: AI | H18: Không thể kiểm tra focus-order vì control tăng/giảm số lượng không tồn tại. Evidence: GUI_13_14.png Path: ../evidence/hw03/Chrome/GUI_13_14.png
A19: GUI-15 | B19: Checkout | C19: IA-02 | D19: Mọi trường bắt buộc của thông tin giao hàng/thanh toán có nhãn rõ và ký hiệu *; nhãn vẫn hiểu được sau khi người dùng nhập dữ liệu. | E19: User ở Checkout với giỏ hợp lệ. | F19: FAILED | G19: AI | H19: Không có dấu * hoặc dấu hiệu nào cho trường bắt buộc. Evidence: GUI_15_16.png Path: ../evidence/hw03/Chrome/GUI_15_16.png
A20: GUI-16 | B20: Checkout | C20: IA-02 | D20: Gửi form khi bỏ trống trường bắt buộc không tạo đơn; thông báo lỗi cụ thể xuất hiện gần trường liên quan và phía trên nút submit. | E20: Để trống lần lượt từng trường bắt buộc rồi gửi form. | F20: BLOCKED | G20: AI | H20: Checkout không có bất kỳ trường thông tin giao hàng/thanh toán bắt buộc nào để kiểm tra việc chặn submit khi bỏ trống; do đó không thể tái hiện đúng kịch bản của item này. Evidence: GUI_15_16.png Path: ../evidence/hw03/Chrome/GUI_15_16.png
A21: GUI-17 | B21: Checkout | C21: IA-02 | D21: Với toàn bộ dữ liệu hợp lệ, form chấp nhận gửi; dữ liệu trong phần tóm tắt và tổng tiền không trở thành trường cho phép chỉnh sửa trực tiếp. | E21: Nhập thông tin giao hàng/thanh toán hợp lệ; giỏ không rỗng. | F21: FAILED | G21: AI | H21: Ô Tổng tiền thanh toán là input có thể chỉnh sửa trực tiếp bằng bàn phím, không phải trường chỉ đọc như kỳ vọng. Evidence: GUI_17.png Path: ../evidence/hw03/Chrome/GUI_17.png
A22: GUI-18 | B22: Coupon section | C22: IA-02 | D22: Ô coupon có nhãn hoặc tên truy cập được; thứ tự Tab đi từ ô mã đến nút Áp dụng rồi đến hành động checkout kế tiếp. | E22: User ở Checkout; thao tác chỉ bằng bàn phím. | F22: PASSED | G22: AI
A23: GUI-19 | B23: Coupon section | C23: IA-02 | D23: Bấm Áp dụng khi ô coupon rỗng không làm thay đổi tổng tiền và hiển thị hướng dẫn/lỗi rõ ràng gần khu vực coupon. | E23: Ô coupon để trống. | F23: PASSED | G23: AI
A24: GUI-20 | B24: Coupon section | C24: IA-02 | D24: Mã hợp lệ được chấp nhận dù người dùng nhập chữ thường/chữ hoa theo quy tắc hiển thị của UI; khoảng trắng đầu/cuối không gây phản hồi mơ hồ. | E24: Thử SAVE10, save10 và SAVE10. | F24: PASSED | G24: AI
A25: GUI-21 | B25: Checkout Success | C25: IA-02 | D25: Sau khi đơn đã hoàn tất, màn hình không còn form thanh toán hoặc nút submit đang hoạt động có thể vô tình gửi lại đơn. | E25: Vừa hoàn tất một đơn hàng hợp lệ. | F25: PASSED | G25: AI
A26: GUI-22 | B26: Checkout Success | C26: IA-02 | D26: Thông tin đơn hàng đã xác nhận được trình bày ở trạng thái chỉ đọc; thứ tự focus không đi vào các trường chỉnh sửa giao hàng/thanh toán cũ. | E26: Dùng Tab duyệt toàn bộ màn hình thành công. | F26: PASSED | G26: AI
A27: GUI-23 | B27: Admin Coupon Management | C27: IA-02 | D27: Tất cả trường bắt buộc khi tạo coupon — mã, loại, giá trị giảm, ngày hết hạn, đơn tối thiểu và giới hạn/người — có nhãn rõ, ký hiệu * và liên kết dễ nhận biết với control tương ứng. | E27: Admin mở form tạo coupon. | F27: FAILED | G27: AI | H27: Form tạo coupon không hiển thị ký hiệu * cho các trường bắt buộc; các ô nhập chủ yếu chỉ dùng placeholder, không có nhãn văn bản riêng hiển thị cạnh từng control. Evidence: GUI_23_33_34.png Path: ../evidence/hw03/Chrome/GUI_23_33_34.png
A28: GUI-24 | B28: Admin Coupon Management | C28: IA-02 | D28: Form chặn dữ liệu ngoài miền và chỉ rõ lỗi tại trường: mã trùng/rỗng, giá trị giảm không dương, đơn tối thiểu âm, ngày hết hạn không hợp lệ, giới hạn/người nhỏ hơn 1. | E28: Chuẩn bị lần lượt các bộ dữ liệu không hợp lệ nêu trong check. | F28: PASSED | G28: AI
A29: GUI-25 | B29: Cart | C29: IA-03 | D29: Nút/đường dẫn Tiếp tục mua sắm đưa user về trang sản phẩm và trình duyệt Back quay lại Cart mà không tạo điều hướng vòng lặp. | E29: User ở Cart có ít nhất 1 sản phẩm. | F29: PASSED | G29: AI
A30: GUI-26 | B30: Cart | C30: IA-03 | D30: Nút tiến tới Checkout điều hướng đúng màn hình; breadcrumb/navbar thể hiện Cart là vị trí hiện tại trước khi chuyển bước. | E30: User thường đã đăng nhập; giỏ không rỗng. | F30: FAILED | G30: AI | H30: Không có breadcrumb/navbar/step indicator nào thể hiện Cart là bước hiện tại trước khi chuyển sang Checkout. Evidence: GUI_26_27_36.png Path: ../evidence/hw03/Chrome/GUI_26_27_36.png
A31: GUI-27 | B31: Checkout | C31: IA-03 | D31: Luồng Cart → Checkout thể hiện bước hiện tại rõ ràng bằng breadcrumb/navbar/step indicator và không làm người dùng mất phương hướng. | E31: Đi từ Cart sang Checkout bằng hành động chính. | F31: FAILED | G31: AI | H31: Luồng Cart → Checkout không có breadcrumb/step indicator nào thể hiện bước hiện tại. Evidence: GUI_26_27_36.png Path: ../evidence/hw03/Chrome/GUI_26_27_36.png
A32: GUI-28 | B32: Checkout | C32: IA-03 | D32: Hành động quay lại Cart và nút Back của Chrome đều trở lại Cart hợp lý, không tự tạo đơn và không làm mất nội dung giỏ. | E32: Checkout đã nhập một phần thông tin; giỏ có sản phẩm. | F32: PASSED | G32: AI
A33: GUI-29 | B33: Coupon section | C33: IA-03 | D33: Người dùng có thể áp dụng coupon trong Checkout mà không bị điều hướng sang trang không liên quan hoặc mất vị trí trong luồng thanh toán. | E33: Nhập một mã coupon và chọn Áp dụng. | F33: PASSED | G33: AI
A34: GUI-30 | B34: Coupon section | C34: IA-03 | D34: Sau khi xử lý coupon, focus/điểm nhìn ở lại khu vực phản hồi hoặc chuyển hợp lý tới tổng đơn hàng để người dùng hiểu kết quả trước khi tiếp tục. | E34: Thử một mã hợp lệ và một mã không hợp lệ bằng bàn phím. | F34: PASSED | G34: AI
A35: GUI-31 | B35: Checkout Success | C35: IA-03 | D35: Màn hình cung cấp hành động tiếp theo rõ ràng, chẳng hạn Tiếp tục mua sắm hoặc xem đơn hàng, và điều hướng tới đúng đích. | E35: Hoàn tất đơn hàng hợp lệ. | F35: PASSED | G35: AI
A36: GUI-32 | B36: Checkout Success | C36: IA-03 | D36: Refresh, Back và Forward không đưa người dùng trở lại form có thể gửi lại cùng đơn hoặc tạo thêm đơn ngoài ý muốn. | E36: Đang ở màn hình thành công của một đơn vừa tạo. | F36: PASSED | G36: AI
A37: GUI-33 | B37: Admin Coupon Management | C37: IA-03 | D37: Mục Coupon trong điều hướng admin đưa đến đúng màn hình, có trạng thái đang chọn rõ ràng; Back/Forward giữ luồng điều hướng dễ hiểu. | E37: Admin đã đăng nhập và đi từ màn hình admin khác sang Coupon. | F37: FAILED | G37: AI | H37: Mục “Mã Giảm Giá” được highlight màu xanh và mở đúng màn hình “Quản lý Mã Giảm Giá”; Khi ấn backward thì lại ra trang chủ trình duyệt thay vì tab trước đó. Evidence: GUI_23_33_34.png Path: ../evidence/hw03/Chrome/GUI_23_33_34.png
A38: GUI-34 | B38: Admin Coupon Management | C38: IA-03 | D38: Luồng xem danh sách → tạo/xóa coupon → quay lại danh sách có hành động rõ ràng; không có control tạo, sửa, xóa hoặc hủy nào dẫn đến màn hình sai hay ngõ cụt. | E38: Admin mở danh sách; có dữ liệu dùng riêng cho kiểm thử thao tác. | F38: FAILED | G38: AI | H38: Không có luồng tách biệt xem/tạo/sửa/xóa; toàn bộ gộp trên một màn hình. Evidence: GUI_23_33_34.png Path: ../evidence/hw03/Chrome/GUI_23_33_34.png
A39: GUI-35 | B39: Cart | C39: IA-04 | D39: Cart rỗng hiển thị icon/hình minh họa, thông báo thân thiện và hành động tiếp tục mua sắm; không hiển thị tổng tiền hoặc CTA checkout gây hiểu nhầm. | E39: User thường đăng nhập với giỏ rỗng. | F39: PASSED | G39: AI
A40: GUI-36 | B40: Cart | C40: IA-04 | D40: Xóa sản phẩm yêu cầu xác nhận; Hủy giữ nguyên dòng, Xác nhận xóa cập nhật danh sách, tổng tiền và badge giỏ ngay, kèm phản hồi nhìn thấy được. | E40: Giỏ có ít nhất 2 sản phẩm. | F40: FAILED | G40: AI | H40: Xóa sản phẩm không có hộp thoại xác nhận; sản phẩm bị xóa ngay khi bấm. Evidence: GUI_26_27_36.png Path: ../evidence/hw03/Chrome/GUI_26_27_36.png
A41: GUI-37 | B41: Checkout | C41: IA-04 | D41: Trong lúc gửi đơn, nút submit có trạng thái đang xử lý/disabled rõ ràng và nhiều lần click nhanh không tạo phản hồi hoặc đơn trùng. | E41: Dữ liệu checkout hợp lệ; mô phỏng click liên tiếp. | F41: PASSED | G41: AI
...

Sheet 02_Human Review
A1: HUMAN-REVIEW ADDITIONS — 5 ITEMS
A2: Giữ nguyên 8 cột và toàn bộ nội dung từ bảng “Human-review additions” trong file Markdown.
A4: Added ID | B4: Screen | C4: IA | D4: Human-added check | E4: Why AI may have missed it | F4: Status | G4: Origin | H4: Evidence / notes
A5: GUI-047 | B5: Cart | C5: IA-04 | D5: Cart — tổng tiền có tính đúng khi giỏ có dòng trùng sản phẩm do lỗi thêm lại không cộng dồn | E5: Hành vi phụ thuộc trạng thái lỗi hiếm gặp với các dòng sản phẩm trùng. | F5: PASSED | G5: Human | H5: Tổng tiền hiển thị đúng khi giỏ có 2 dòng cùng sản phẩm, mỗi dòng số lượng 1.
A6: GUI-48 | B6: Admin Coupon Management | C6: IA-02 | D6: Admin Coupon Management — thứ tự Tab bàn phím khi di chuyển giữa danh sách, form tạo và nút sửa/xóa gộp chung 1 màn hình | E6: Sắc thái accessibility của nhiều vùng tương tác gộp trong một màn hình. | F6: PASSED | G6: Human | H6: Ảnh cho thấy form tạo coupon và danh sách coupon với các nút Xóa được gộp trên cùng một màn hình;. Evidence: GUI_48.png Path: ../evidence/hw03/Chrome/GUI_48.png
A7: GUI-49 | B7: Coupon section | C7: IA-01 | D7: Coupon section — nhãn hiển thị loại coupon percent có khớp chiều hướng tính toán thực tế | E7: Kỳ vọng ngữ nghĩa giữa nhãn hiển thị và kết quả tính toán có thể mơ hồ. | F7: FAILED | G7: Human | H7: Nhãn hiển thị “Giảm 10%” đúng, nhưng tổng tiền tăng từ 103.000.000 ₫ lên 1.030.000.000 ₫ nên kết quả cuối cùng không phù hợp. Evidence: GUI_07_49.png Path: ../evidence/hw03/Chrome/GUI_07_49.png
A8: GUI-50 | B8: Checkout | C8: IA-04 | D8: Checkout — dữ liệu form có bị mất khi refresh giữa chừng khi không có cảnh báo rời trang | E8: Hành vi lưu trạng thái chỉ xuất hiện qua chuyển tiếp refresh giữa chừng. | F8: FAILED | G8: Human | H8: Nếu đang trong quá trình nhập mà refresh, UI hiển thị 404: NOT_FOUND. Evidence: GUI_50.png Path: ../evidence/hw03/Chrome/GUI_50.png
A9: GUI-51 | B9: Cart | C9: IA-04 | D9: Khi thêm lại một sản phẩm đã có trong giỏ, hệ thống hiển thị thêm 1 dòng mới trùng tên thay vì cộng dồn số lượng vào dòng đã có | E9: Đây là hành vi runtime chỉ lộ ra khi tự tay thêm lại sản phẩm trùng, không thể suy luận được từ mô tả giao diện tĩnh ban đầu | F9: FAILED | G9: Human | H9: Giỏ hàng hiển thị 2 dòng 'Samsung Galaxy S24 Ultra' riêng biệt, mỗi dòng số lượng 1, thay vì gộp thành 1 dòng số lượng 2. Evidence: GUI_13_14.png Path: ../evidence/hw03/Chrome/GUI_13_14.png

Sheet 03_All Items
A1: ALL CHECKLIST ITEMS — 51 ITEMS
A2: Bảng tổng hợp chuẩn hóa từ GUI checklist và Human-review additions để dễ lọc và phân tích.
A4: ID | B4: Source | C4: Screen | D4: IA | E4: Check / Expected Result | F4: Test Data / Precondition / Review Rationale | G4: Status | H4: Origin | I4: Evidence / Notes
A5: GUI-01 | B5: GUI checklist | C5: Cart | D5: IA-01 | E5: Tiêu đề trang và toàn bộ nhãn chính hiển thị rõ ràng, thống nhất bằng tiếng Việt, không có chuỗi lỗi font hoặc ký tự bị vỡ. | F5: User thường đã đăng nhập; giỏ có ít nhất 1 sản phẩm. | G5: PASSED | H5: AI
A6: GUI-02 | B6: GUI checklist | C6: Cart | D6: IA-01 | E6: Danh sách sản phẩm thể hiện rõ các thông tin Sản phẩm, Đơn giá, Số lượng, Thành tiền và Thao tác; các cột thẳng hàng, không chồng lấn tại viewport 1440 × 900. | F6: Giỏ có ít nhất 2 sản phẩm với tên dài/ngắn khác nhau. | G6: PASSED | H6: AI
A7: GUI-03 | B7: GUI checklist | C7: Cart | D7: IA-01 | E7: Đơn giá, thành tiền từng dòng và Tổng cộng dùng ký hiệu ₫, có phân cách hàng nghìn và cùng một quy tắc định dạng. | F7: Giỏ có ít nhất 1 sản phẩm; tổng tiền từ 1.000 ₫ trở lên. | G7: PASSED | H7: AI
A8: GUI-04 | B8: GUI checklist | C8: Checkout | D8: IA-01 | E8: Tiêu đề Checkout/Thanh toán, thông tin giao hàng và phần tóm tắt đơn hàng có phân cấp thị giác rõ, không bị cắt hoặc chồng lấn tại viewport 1440 × 900. | F8: User thường đã đăng nhập; giỏ không rỗng; mở Checkout. | G8: PASSED | H8: AI
A9: GUI-05 | B9: GUI checklist | C9: Checkout | D9: IA-01 | E9: Tên sản phẩm, số lượng, giá, tổng tiền và nút hoàn tất thanh toán dễ đọc; nút hành động chính có kiểu hiển thị nhất quán với hành động tích cực. | F9: Checkout có ít nhất 2 sản phẩm. | G9: PASSED | H9: AI
A10: GUI-06 | B10: GUI checklist | C10: Coupon section | D10: IA-01 | E10: Nhãn/placeholder ô mã giảm giá và nút áp dụng mô tả rõ mục đích, dùng ngôn ngữ nhất quán và không phụ thuộc riêng vào biểu tượng. | F10: User ở Checkout; khu vực coupon đang hiển thị. | G10: PASSED | H10: AI
A11: GUI-07 | B11: GUI checklist | C11: Coupon section | D11: IA-01 | E11: Giá trị giảm, tổng trước giảm và tổng sau giảm dùng ký hiệu ₫, phân cách hàng nghìn; phần trăm dùng % đúng và dễ phân biệt. | F11: Giỏ đủ điều kiện dùng một coupon percent và một coupon fixed. | G11: FAILED | H11: AI | I11: Coupon SAVE10 tăng giá thay vì giảm, sai logic áp dụng, không phải lỗi định dạng. Evidence: GUI_07_49.png Path: ../evidence/hw03/Chrome/GUI_07_49.png
A12: GUI-08 | B12: GUI checklist | C12: Checkout Success | D12: IA-01 | E12: Trạng thái đặt hàng thành công nổi bật, dễ nhận biết, không chỉ truyền đạt bằng màu sắc và không lẫn với nội dung phụ. | F12: Hoàn tất một đơn hàng hợp lệ. | G12: PASSED | H12: AI
A13: GUI-09 | B13: GUI checklist | C13: Checkout Success | D13: IA-01 | E13: Mã đơn, tổng tiền và thông tin xác nhận (nếu hiển thị) có nhãn rõ, định dạng nhất quán và không bị cắt ở 1440 × 900. | F13: Vừa hoàn tất một đơn hàng có tổng từ 1.000 ₫ trở lên. | G13: PASSED | H13: AI
A14: GUI-10 | B14: GUI checklist | C14: Admin Coupon Management | D14: IA-01 | E14: Tiêu đề quản lý coupon, khu vực tạo mới và danh sách coupon có phân cấp rõ; bảng không chồng lấn hoặc mất cột ở 1440 × 900. | F14: Admin đã đăng nhập; mở quản lý coupon; có ít nhất 2 coupon. | G14: PASSED | H14: AI
A15: GUI-11 | B15: GUI checklist | C15: Admin Coupon Management | D15: IA-01 | E15: Các cột Mã, Loại, Giá trị, Đơn tối thiểu, Hết hạn, Giới hạn/người và Hành động có nhãn dễ hiểu, căn chỉnh nhất quán. | F15: Danh sách có cả coupon percent và fixed. | G15: PASSED | H15: AI
A16: GUI-12 | B16: GUI checklist | C16: Admin Coupon Management | D16: IA-01 | E16: Ngày hết hạn, giá trị coupon, đơn tối thiểu và số lượt dùng được định dạng theo đúng loại dữ liệu; coupon hết hạn được phân biệt bằng cả chữ và kiểu hiển thị dễ đọc. | F16: Có coupon còn hạn và coupon hết hạn. | G16: PASSED | H16: AI
A17: GUI-13 | B17: GUI checklist | C17: Cart | D17: IA-02 | E17: Điều khiển số lượng có nhãn/biểu tượng dễ hiểu, vùng bấm rõ ràng và không cho người dùng tạo số lượng nhỏ hơn 1. | F17: Giỏ có 1 sản phẩm với số lượng 1. | G17: BLOCKED | H17: AI | I17: Không thể kiểm tra min-quantity vì control tăng/giảm số lượng không tồn tại. Evidence: GUI_13_14.png Path: ../evidence/hw03/Chrome/GUI_13_14.png
A18: GUI-14 | B18: GUI checklist | C18: Cart | D18: IA-02 | E18: Khi thay đổi số lượng bằng bàn phím hoặc điều khiển tăng/giảm, focus vẫn nhìn thấy và thứ tự Tab đi theo trình tự thị giác hợp lý. | F18: Giỏ có ít nhất 2 sản phẩm; thao tác chỉ bằng bàn phím. | G18: BLOCKED | H18: AI | I18: Không thể kiểm tra focus-order vì control tăng/giảm số lượng không tồn tại. Evidence: GUI_13_14.png Path: ../evidence/hw03/Chrome/GUI_13_14.png
A19: GUI-15 | B19: GUI checklist | C19: Checkout | D19: IA-02 | E19: Mọi trường bắt buộc của thông tin giao hàng/thanh toán có nhãn rõ và ký hiệu *; nhãn vẫn hiểu được sau khi người dùng nhập dữ liệu. | F19: User ở Checkout với giỏ hợp lệ. | G19: FAILED | H19: AI | I19: Không có dấu * hoặc dấu hiệu nào cho trường bắt buộc. Evidence: GUI_15_16.png Path: ../evidence/hw03/Chrome/GUI_15_16.png
A20: GUI-16 | B20: GUI checklist | C20: Checkout | D20: IA-02 | E20: Gửi form khi bỏ trống trường bắt buộc không tạo đơn; thông báo lỗi cụ thể xuất hiện gần trường liên quan và phía trên nút submit. | F20: Để trống lần lượt từng trường bắt buộc rồi gửi form. | G20: BLOCKED | H20: AI | I20: Checkout không có bất kỳ trường thông tin giao hàng/thanh toán bắt buộc nào để kiểm tra việc chặn submit khi bỏ trống; do đó không thể tái hiện đúng kịch bản của item này. Evidence: GUI_15_16.png Path: ../evidence/hw03/Chrome/GUI_15_16.png
A21: GUI-17 | B21: GUI checklist | C21: Checkout | D21: IA-02 | E21: Với toàn bộ dữ liệu hợp lệ, form chấp nhận gửi; dữ liệu trong phần tóm tắt và tổng tiền không trở thành trường cho phép chỉnh sửa trực tiếp. | F21: Nhập thông tin giao hàng/thanh toán hợp lệ; giỏ không rỗng. | G21: FAILED | H21: AI | I21: Ô Tổng tiền thanh toán là input có thể chỉnh sửa trực tiếp bằng bàn phím, không phải trường chỉ đọc như kỳ vọng. Evidence: GUI_17.png Path: ../evidence/hw03/Chrome/GUI_17.png
A22: GUI-18 | B22: GUI checklist | C22: Coupon section | D22: IA-02 | E22: Ô coupon có nhãn hoặc tên truy cập được; thứ tự Tab đi từ ô mã đến nút Áp dụng rồi đến hành động checkout kế tiếp. | F22: User ở Checkout; thao tác chỉ bằng bàn phím. | G22: PASSED | H22: AI
A23: GUI-19 | B23: GUI checklist | C23: Coupon section | D23: IA-02 | E23: Bấm Áp dụng khi ô coupon rỗng không làm thay đổi tổng tiền và hiển thị hướng dẫn/lỗi rõ ràng gần khu vực coupon. | F23: Ô coupon để trống. | G23: PASSED | H23: AI
A24: GUI-20 | B24: GUI checklist | C24: Coupon section | D24: IA-02 | E24: Mã hợp lệ được chấp nhận dù người dùng nhập chữ thường/chữ hoa theo quy tắc hiển thị của UI; khoảng trắng đầu/cuối không gây phản hồi mơ hồ. | F24: Thử SAVE10, save10 và SAVE10. | G24: PASSED | H24: AI
A25: GUI-21 | B25: GUI checklist | C25: Checkout Success | D25: IA-02 | E25: Sau khi đơn đã hoàn tất, màn hình không còn form thanh toán hoặc nút submit đang hoạt động có thể vô tình gửi lại đơn. | F25: Vừa hoàn tất một đơn hàng hợp lệ. | G25: PASSED | H25: AI
A26: GUI-22 | B26: GUI checklist | C26: Checkout Success | D26: IA-02 | E26: Thông tin đơn hàng đã xác nhận được trình bày ở trạng thái chỉ đọc; thứ tự focus không đi vào các trường chỉnh sửa giao hàng/thanh toán cũ. | F26: Dùng Tab duyệt toàn bộ màn hình thành công. | G26: PASSED | H26: AI
A27: GUI-23 | B27: GUI checklist | C27: Admin Coupon Management | D27: IA-02 | E27: Tất cả trường bắt buộc khi tạo coupon — mã, loại, giá trị giảm, ngày hết hạn, đơn tối thiểu và giới hạn/người — có nhãn rõ, ký hiệu * và liên kết dễ nhận biết với control tương ứng. | F27: Admin mở form tạo coupon. | G27: FAILED | H27: AI | I27: Form tạo coupon không hiển thị ký hiệu * cho các trường bắt buộc; các ô nhập chủ yếu chỉ dùng placeholder, không có nhãn văn bản riêng hiển thị cạnh từng control. Evidence: GUI_23_33_34.png Path: ../evidence/hw03/Chrome/GUI_23_33_34.png
A28: GUI-24 | B28: GUI checklist | C28: Admin Coupon Management | D28: IA-02 | E28: Form chặn dữ liệu ngoài miền và chỉ rõ lỗi tại trường: mã trùng/rỗng, giá trị giảm không dương, đơn tối thiểu âm, ngày hết hạn không hợp lệ, giới hạn/người nhỏ hơn 1. | F28: Chuẩn bị lần lượt các bộ dữ liệu không hợp lệ nêu trong check. | G28: PASSED | H28: AI
A29: GUI-25 | B29: GUI checklist | C29: Cart | D29: IA-03 | E29: Nút/đường dẫn Tiếp tục mua sắm đưa user về trang sản phẩm và trình duyệt Back quay lại Cart mà không tạo điều hướng vòng lặp. | F29: User ở Cart có ít nhất 1 sản phẩm. | G29: PASSED | H29: AI
A30: GUI-26 | B30: GUI checklist | C30: Cart | D30: IA-03 | E30: Nút tiến tới Checkout điều hướng đúng màn hình; breadcrumb/navbar thể hiện Cart là vị trí hiện tại trước khi chuyển bước. | F30: User thường đã đăng nhập; giỏ không rỗng. | G30: FAILED | H30: AI | I30: Không có breadcrumb/navbar/step indicator nào thể hiện Cart là bước hiện tại trước khi chuyển sang Checkout. Evidence: GUI_26_27_36.png Path: ../evidence/hw03/Chrome/GUI_26_27_36.png
A31: GUI-27 | B31: GUI checklist | C31: Checkout | D31: IA-03 | E31: Luồng Cart → Checkout thể hiện bước hiện tại rõ ràng bằng breadcrumb/navbar/step indicator và không làm người dùng mất phương hướng. | F31: Đi từ Cart sang Checkout bằng hành động chính. | G31: FAILED | H31: AI | I31: Luồng Cart → Checkout không có breadcrumb/step indicator nào thể hiện bước hiện tại. Evidence: GUI_26_27_36.png Path: ../evidence/hw03/Chrome/GUI_26_27_36.png
A32: GUI-28 | B32: GUI checklist | C32: Checkout | D32: IA-03 | E32: Hành động quay lại Cart và nút Back của Chrome đều trở lại Cart hợp lý, không tự tạo đơn và không làm mất nội dung giỏ. | F32: Checkout đã nhập một phần thông tin; giỏ có sản phẩm. | G32: PASSED | H32: AI
A33: GUI-29 | B33: GUI checklist | C33: Coupon section | D33: IA-03 | E33: Người dùng có thể áp dụng coupon trong Checkout mà không bị điều hướng sang trang không liên quan hoặc mất vị trí trong luồng thanh toán. | F33: Nhập một mã coupon và chọn Áp dụng. | G33: PASSED | H33: AI
A34: GUI-30 | B34: GUI checklist | C34: Coupon section | D34: IA-03 | E34: Sau khi xử lý coupon, focus/điểm nhìn ở lại khu vực phản hồi hoặc chuyển hợp lý tới tổng đơn hàng để người dùng hiểu kết quả trước khi tiếp tục. | F34: Thử một mã hợp lệ và một mã không hợp lệ bằng bàn phím. | G34: PASSED | H34: AI
A35: GUI-31 | B35: GUI checklist | C35: Checkout Success | D35: IA-03 | E35: Màn hình cung cấp hành động tiếp theo rõ ràng, chẳng hạn Tiếp tục mua sắm hoặc xem đơn hàng, và điều hướng tới đúng đích. | F35: Hoàn tất đơn hàng hợp lệ. | G35: PASSED | H35: AI
A36: GUI-32 | B36: GUI checklist | C36: Checkout Success | D36: IA-03 | E36: Refresh, Back và Forward không đưa người dùng trở lại form có thể gửi lại cùng đơn hoặc tạo thêm đơn ngoài ý muốn. | F36: Đang ở màn hình thành công của một đơn vừa tạo. | G36: PASSED | H36: AI
A37: GUI-33 | B37: GUI checklist | C37: Admin Coupon Management | D37: IA-03 | E37: Mục Coupon trong điều hướng admin đưa đến đúng màn hình, có trạng thái đang chọn rõ ràng; Back/Forward giữ luồng điều hướng dễ hiểu. | F37: Admin đã đăng nhập và đi từ màn hình admin khác sang Coupon. | G37: FAILED | H37: AI | I37: Mục “Mã Giảm Giá” được highlight màu xanh và mở đúng màn hình “Quản lý Mã Giảm Giá”; Khi ấn backward thì lại ra trang chủ trình duyệt thay vì tab trước đó. Evidence: GUI_23_33_34.png Path: ../evidence/hw03/Chrome/GUI_23_33_34.png
A38: GUI-34 | B38: GUI checklist | C38: Admin Coupon Management | D38: IA-03 | E38: Luồng xem danh sách → tạo/xóa coupon → quay lại danh sách có hành động rõ ràng; không có control tạo, sửa, xóa hoặc hủy nào dẫn đến màn hình sai hay ngõ cụt. | F38: Admin mở danh sách; có dữ liệu dùng riêng cho kiểm thử thao tác. | G38: FAILED | H38: AI | I38: Không có luồng tách biệt xem/tạo/sửa/xóa; toàn bộ gộp trên một màn hình. Evidence: GUI_23_33_34.png Path: ../evidence/hw03/Chrome/GUI_23_33_34.png
A39: GUI-35 | B39: GUI checklist | C39: Cart | D39: IA-04 | E39: Cart rỗng hiển thị icon/hình minh họa, thông báo thân thiện và hành động tiếp tục mua sắm; không hiển thị tổng tiền hoặc CTA checkout gây hiểu nhầm. | F39: User thường đăng nhập với giỏ rỗng. | G39: PASSED | H39: AI
A40: GUI-36 | B40: GUI checklist | C40: Cart | D40: IA-04 | E40: Xóa sản phẩm yêu cầu xác nhận; Hủy giữ nguyên dòng, Xác nhận xóa cập nhật danh sách, tổng tiền và badge giỏ ngay, kèm phản hồi nhìn thấy được. | F40: Giỏ có ít nhất 2 sản phẩm. | G40: FAILED | H40: AI | I40: Xóa sản phẩm không có hộp thoại xác nhận; sản phẩm bị xóa ngay khi bấm. Evidence: GUI_26_27_36.png Path: ../evidence/hw03/Chrome/GUI_26_27_36.png
A41: GUI-37 | B41: GUI checklist | C41: Checkout | D41: IA-04 | E41: Trong lúc gửi đơn, nút submit có trạng thái đang xử lý/disabled rõ ràng và nhiều lần click nhanh không tạo phản hồi hoặc đơn trùng. | F41: Dữ liệu checkout hợp lệ; mô phỏng click liên tiếp. | G41: PASSED | H41: AI
...

Sheet 04_Analysis
A1: Analysis
A3: Các số liệu bên dưới được tính từ sheet 03_All Items bằng công thức Excel.
A5: IA | B5: Total | C5: Passed | D5: Failed | E5: Blocked
A6: IA-01 | B6: =COUNTIF('03_All Items'!$D$5:$D$55,A6) -> 13 | C6: =COUNTIFS('03_All Items'!$D$5:$D$55,A6,'03_All Items'!$G$5:$G$55,"PASSED") -> 11 | D6: =COUNTIFS('03_All Items'!$D$5:$D$55,A6,'03_All Items'!$G$5:$G$55,"FAILED") -> 2 | E6: =COUNTIFS('03_All Items'!$D$5:$D$55,A6,'03_All Items'!$G$5:$G$55,"BLOCKED") -> 0
A7: IA-02 | B7: =COUNTIF('03_All Items'!$D$5:$D$55,A7) -> 13 | C7: =COUNTIFS('03_All Items'!$D$5:$D$55,A7,'03_All Items'!$G$5:$G$55,"PASSED") -> 7 | D7: =COUNTIFS('03_All Items'!$D$5:$D$55,A7,'03_All Items'!$G$5:$G$55,"FAILED") -> 3 | E7: =COUNTIFS('03_All Items'!$D$5:$D$55,A7,'03_All Items'!$G$5:$G$55,"BLOCKED") -> 3
A8: IA-03 | B8: =COUNTIF('03_All Items'!$D$5:$D$55,A8) -> 10 | C8: =COUNTIFS('03_All Items'!$D$5:$D$55,A8,'03_All Items'!$G$5:$G$55,"PASSED") -> 6 | D8: =COUNTIFS('03_All Items'!$D$5:$D$55,A8,'03_All Items'!$G$5:$G$55,"FAILED") -> 4 | E8: =COUNTIFS('03_All Items'!$D$5:$D$55,A8,'03_All Items'!$G$5:$G$55,"BLOCKED") -> 0
A9: IA-04 | B9: =COUNTIF('03_All Items'!$D$5:$D$55,A9) -> 15 | C9: =COUNTIFS('03_All Items'!$D$5:$D$55,A9,'03_All Items'!$G$5:$G$55,"PASSED") -> 8 | D9: =COUNTIFS('03_All Items'!$D$5:$D$55,A9,'03_All Items'!$G$5:$G$55,"FAILED") -> 7 | E9: =COUNTIFS('03_All Items'!$D$5:$D$55,A9,'03_All Items'!$G$5:$G$55,"BLOCKED") -> 0
A13: Screen | B13: Total | C13: Passed | D13: Failed | E13: Blocked
A14: Cart | B14: =COUNTIF('03_All Items'!$C$5:$C$55,A14) -> 11 | C14: =COUNTIFS('03_All Items'!$C$5:$C$55,A14,'03_All Items'!$G$5:$G$55,"PASSED") -> 6 | D14: =COUNTIFS('03_All Items'!$C$5:$C$55,A14,'03_All Items'!$G$5:$G$55,"FAILED") -> 3 | E14: =COUNTIFS('03_All Items'!$C$5:$C$55,A14,'03_All Items'!$G$5:$G$55,"BLOCKED") -> 2
A15: Checkout | B15: =COUNTIF('03_All Items'!$C$5:$C$55,A15) -> 10 | C15: =COUNTIFS('03_All Items'!$C$5:$C$55,A15,'03_All Items'!$G$5:$G$55,"PASSED") -> 4 | D15: =COUNTIFS('03_All Items'!$C$5:$C$55,A15,'03_All Items'!$G$5:$G$55,"FAILED") -> 5 | E15: =COUNTIFS('03_All Items'!$C$5:$C$55,A15,'03_All Items'!$G$5:$G$55,"BLOCKED") -> 1
A16: Coupon section | B16: =COUNTIF('03_All Items'!$C$5:$C$55,A16) -> 10 | C16: =COUNTIFS('03_All Items'!$C$5:$C$55,A16,'03_All Items'!$G$5:$G$55,"PASSED") -> 8 | D16: =COUNTIFS('03_All Items'!$C$5:$C$55,A16,'03_All Items'!$G$5:$G$55,"FAILED") -> 2 | E16: =COUNTIFS('03_All Items'!$C$5:$C$55,A16,'03_All Items'!$G$5:$G$55,"BLOCKED") -> 0
A17: Checkout Success | B17: =COUNTIF('03_All Items'!$C$5:$C$55,A17) -> 9 | C17: =COUNTIFS('03_All Items'!$C$5:$C$55,A17,'03_All Items'!$G$5:$G$55,"PASSED") -> 8 | D17: =COUNTIFS('03_All Items'!$C$5:$C$55,A17,'03_All Items'!$G$5:$G$55,"FAILED") -> 1 | E17: =COUNTIFS('03_All Items'!$C$5:$C$55,A17,'03_All Items'!$G$5:$G$55,"BLOCKED") -> 0
A18: Admin Coupon Management | B18: =COUNTIF('03_All Items'!$C$5:$C$55,A18) -> 11 | C18: =COUNTIFS('03_All Items'!$C$5:$C$55,A18,'03_All Items'!$G$5:$G$55,"PASSED") -> 6 | D18: =COUNTIFS('03_All Items'!$C$5:$C$55,A18,'03_All Items'!$G$5:$G$55,"FAILED") -> 5 | E18: =COUNTIFS('03_All Items'!$C$5:$C$55,A18,'03_All Items'!$G$5:$G$55,"BLOCKED") -> 0
